<?xml version="1.0" encoding="utf-8"?>
<!-- This URDF was automatically created by SolidWorks to URDF Exporter! Originally created by Stephen Brawner (brawner@gmail.com) 
     Commit Version: 1.6.0-1-g15f4949  Build Version: 1.6.7594.29634
     For more information, please see http://wiki.ros.org/sw_urdf_exporter -->
<robot
  name="Spot_dog">
  <link
    name="base_link">
    <inertial>
      <origin
        xyz="0.0023648970233455 -5.91786932781224E-06 -0.0142510828075821"
        rpy="0 0 0" />
      <mass
        value="1.26277058878881" />
      <inertia
        ixx="0.00419953664437585"
        ixy="-5.80918949636821E-09"
        ixz="7.23254112115332E-06"
        iyy="0.00329637735882426"
        iyz="5.41350065581859E-10"
        izz="0.00687786867050381" />
    </inertial>
    <visual>
      <origin
        xyz="0 0 0"
        rpy="0 0 0" />
      <geometry>
        <mesh
          filename="package://Spot_dog/meshes/base_link.STL" />
      </geometry>
      <material
        name="">
        <color
          rgba="0.752941176470588 0.752941176470588 0.752941176470588 1" />
      </material>
    </visual>
    <collision>
      <origin
        xyz="0 0 0"
        rpy="0 0 0" />
      <geometry>
        <mesh
          filename="package://Spot_dog/meshes/base_link.STL" />
      </geometry>
    </collision>
  </link>
  <link
    name="lidar_link">
    <inertial>
      <origin
        xyz="-0.00576993166002146 -0.000337492823115196 0.0144383216860659"
        rpy="0 0 0" />
      <mass
        value="0.142992069515117" />
      <inertia
        ixx="4.62768458751422E-05"
        ixy="-8.53425878441539E-07"
        ixz="-3.62176045397522E-06"
        iyy="7.34715191336753E-05"
        iyz="2.04241589925864E-07"
        izz="0.000107957357997996" />
    </inertial>
    <visual>
      <origin
        xyz="0 0 0"
        rpy="0 0 0" />
      <geometry>
        <mesh
          filename="package://Spot_dog/meshes/lidar_link.STL" />
      </geometry>
      <material
        name="">
        <color
          rgba="0.792156862745098 0.819607843137255 0.933333333333333 1" />
      </material>
    </visual>
    <collision>
      <origin
        xyz="0 0 0"
        rpy="0 0 0" />
      <geometry>
        <mesh
          filename="package://Spot_dog/meshes/lidar_link.STL" />
      </geometry>
    </collision>
  </link>
  <joint
    name="lidar_joint"
    type="fixed">
    <origin
      xyz="0 0 0"
      rpy="0 0 0" />
    <parent
      link="base_link" />
    <child
      link="lidar_link" />
    <axis
      xyz="0 0 0" />
  </joint>
  <link
    name="rf_hip_link">
    <inertial>
      <origin
        xyz="0.0494730376983106 -0.0150434281833299 0.00301418526737343"
        rpy="0 0 0" />
      <mass
        value="0.110796689932405" />
      <inertia
        ixx="4.10359142267942E-05"
        ixy="9.54808544037894E-10"
        ixz="-5.49776572209931E-10"
        iyy="0.00010573669451886"
        iyz="1.80269633038169E-06"
        izz="0.000105542554331478" />
    </inertial>
    <visual>
      <origin
        xyz="0 0 0"
        rpy="0 0 0" />
      <geometry>
        <mesh
          filename="package://Spot_dog/meshes/rf_hip_link.STL" />
      </geometry>
      <material
        name="">
        <color
          rgba="0.752941176470588 0.752941176470588 0.752941176470588 1" />
      </material>
    </visual>
    <collision>
      <origin
        xyz="0 0 0"
        rpy="0 0 0" />
      <geometry>
        <mesh
          filename="package://Spot_dog/meshes/rf_hip_link.STL" />
      </geometry>
    </collision>
  </link>
  <joint
    name="rf_hip_joint"
    type="continuous">
    <origin
      xyz="0.1325 -0.0798899999999921 -0.0342976400491808"
      rpy="0 0 0" />
    <parent
      link="base_link" />
    <child
      link="rf_hip_link" />
    <axis
      xyz="-1 0 0" />
  </joint>
  <link
    name="rf_upper_link">
    <inertial>
      <origin
        xyz="-0.00214105775503137 0.00718603950643993 -0.084916045491464"
        rpy="0 0 0" />
      <mass
        value="0.0381858196620344" />
      <inertia
        ixx="4.56120104484874E-05"
        ixy="-2.39464031883898E-08"
        ixz="-1.71517217998475E-06"
        iyy="4.75905522135306E-05"
        iyz="-6.28798951756866E-07"
        izz="2.56040064315188E-06" />
    </inertial>
    <visual>
      <origin
        xyz="0 0 0"
        rpy="0 0 0" />
      <geometry>
        <mesh
          filename="package://Spot_dog/meshes/rf_upper_link.STL" />
      </geometry>
      <material
        name="">
        <color
          rgba="0.752941176470588 0.752941176470588 0.752941176470588 1" />
      </material>
    </visual>
    <collision>
      <origin
        xyz="0 0 0"
        rpy="0 0 0" />
      <geometry>
        <mesh
          filename="package://Spot_dog/meshes/rf_upper_link.STL" />
      </geometry>
    </collision>
  </link>
  <joint
    name="rf_upper_joint"
    type="continuous">
    <origin
      xyz="0.0269999999999999 -0.0628123830812422 0.0138782034736232"
      rpy="0 0 0" />
    <parent
      link="rf_hip_link" />
    <child
      link="rf_upper_link" />
    <axis
      xyz="0 0.999902556615601 -0.0139598450415945" />
  </joint>
  <link
    name="rf_lower_link">
    <inertial>
      <origin
        xyz="-0.000566464370210601 0.0105757808206226 -0.0662793688967457"
        rpy="0 0 0" />
      <mass
        value="0.0165943030256523" />
      <inertia
        ixx="3.44656313832752E-05"
        ixy="-4.04206417526532E-09"
        ixz="-2.89521143738403E-07"
        iyy="3.50578354061526E-05"
        iyz="-4.80122859437164E-07"
        izz="6.74753139932614E-07" />
    </inertial>
    <visual>
      <origin
        xyz="0 0 0"
        rpy="0 0 0" />
      <geometry>
        <mesh
          filename="package://Spot_dog/meshes/rf_lower_link.STL" />
      </geometry>
      <material
        name="">
        <color
          rgba="0.752941176470588 0.752941176470588 0.752941176470588 1" />
      </material>
    </visual>
    <collision>
      <origin
        xyz="0 0 0"
        rpy="0 0 0" />
      <geometry>
        <mesh
          filename="package://Spot_dog/meshes/rf_lower_link.STL" />
      </geometry>
    </collision>
  </link>
  <joint
    name="rf_lower_joint"
    type="continuous">
    <origin
      xyz="0 -0.00994944374978339 -0.13957706811974"
      rpy="0 0 0" />
    <parent
      link="rf_upper_link" />
    <child
      link="rf_lower_link" />
    <axis
      xyz="0 0.999902556615601 -0.0139598450415923" />
  </joint>
  <link
    name="rf_foot_link">
    <inertial>
      <origin
        xyz="0.00182657432360098 0.00012873580444852 0.00922192075141315"
        rpy="0 0 0" />
      <mass
        value="0.0268070524008249" />
      <inertia
        ixx="8.14223140969403E-06"
        ixy="-1.16761875773851E-08"
        ixz="-8.3657918090591E-07"
        iyy="9.80933505912685E-06"
        iyz="-9.18662196588152E-08"
        izz="3.2302996475183E-06" />
    </inertial>
    <visual>
      <origin
        xyz="0 0 0"
        rpy="0 0 0" />
      <geometry>
        <mesh
          filename="package://Spot_dog/meshes/rf_foot_link.STL" />
      </geometry>
      <material
        name="">
        <color
          rgba="0.752941176470588 0.752941176470588 0.752941176470588 1" />
      </material>
    </visual>
    <collision>
      <origin
        xyz="0 0 0"
        rpy="0 0 0" />
      <geometry>
        <mesh
          filename="package://Spot_dog/meshes/rf_foot_link.STL" />
      </geometry>
    </collision>
  </link>
  <joint
    name="rf_foot_joint"
    type="fixed">
    <origin
      xyz="-0.0068961 0.0093242 -0.16309"
      rpy="0 0 0" />
    <parent
      link="rf_lower_link" />
    <child
      link="rf_foot_link" />
    <axis
      xyz="0 0 0" />
  </joint>
  <link
    name="rh_hip_link">
    <inertial>
      <origin
        xyz="-0.0490434208286332 -0.0122088506344063 0.00336723772986421"
        rpy="0 0 0" />
      <mass
        value="0.125134503525697" />
      <inertia
        ixx="4.20436047435917E-05"
        ixy="9.26208819046283E-10"
        ixz="9.15299288057387E-09"
        iyy="0.000106822835677305"
        iyz="1.8029796501442E-06"
        izz="0.000106637806266663" />
    </inertial>
    <visual>
      <origin
        xyz="0 0 0"
        rpy="0 0 0" />
      <geometry>
        <mesh
          filename="package://Spot_dog/meshes/rh_hip_link.STL" />
      </geometry>
      <material
        name="">
        <color
          rgba="0.752941176470588 0.752941176470588 0.752941176470588 1" />
      </material>
    </visual>
    <collision>
      <origin
        xyz="0 0 0"
        rpy="0 0 0" />
      <geometry>
        <mesh
          filename="package://Spot_dog/meshes/rh_hip_link.STL" />
      </geometry>
    </collision>
  </link>
  <joint
    name="rh_hip_joint"
    type="continuous">
    <origin
      xyz="-0.1325 -0.07989 -0.034298"
      rpy="0 0 0" />
    <parent
      link="base_link" />
    <child
      link="rh_hip_link" />
    <axis
      xyz="-1 0 0" />
  </joint>
  <link
    name="rh_upper_link">
    <inertial>
      <origin
        xyz="-0.00214105772880144 0.00837075421052934 -0.0848074541012483"
        rpy="0 0 0" />
      <mass
        value="0.0381858200550615" />
      <inertia
        ixx="4.56120104509481E-05"
        ixy="-5.31957908588008E-13"
        ixz="-1.71533933666234E-06"
        iyy="4.75993310281756E-05"
        iyz="-1.1924207497845E-12"
        izz="2.55162184449551E-06" />
    </inertial>
    <visual>
      <origin
        xyz="0 0 0"
        rpy="0 0 0" />
      <geometry>
        <mesh
          filename="package://Spot_dog/meshes/rh_upper_link.STL" />
      </geometry>
      <material
        name="">
        <color
          rgba="0.752941176470588 0.752941176470588 0.752941176470588 1" />
      </material>
    </visual>
    <collision>
      <origin
        xyz="0 0 0"
        rpy="0 0 0" />
      <geometry>
        <mesh
          filename="package://Spot_dog/meshes/rh_upper_link.STL" />
      </geometry>
    </collision>
  </link>
  <joint
    name="rh_upper_joint"
    type="continuous">
    <origin
      xyz="-0.0719999999999999 -0.0630000000000001 0.013"
      rpy="0 0 0" />
    <parent
      link="rh_hip_link" />
    <child
      link="rh_upper_link" />
    <axis
      xyz="0 1 0" />
  </joint>
  <link
    name="rh_lower_link">
    <inertial>
      <origin
        xyz="-0.000566464370210656 0.0115 -0.0661252741492748"
        rpy="0 0 0" />
      <mass
        value="0.0165943030256523" />
      <inertia
        ixx="3.44656313832751E-05"
        ixy="-2.11389225358822E-23"
        ixz="-2.89549358407837E-07"
        iyy="3.50645385000434E-05"
        iyz="-3.9261842528959E-21"
        izz="6.68050046041789E-07" />
    </inertial>
    <visual>
      <origin
        xyz="0 0 0"
        rpy="0 0 0" />
      <geometry>
        <mesh
          filename="package://Spot_dog/meshes/rh_lower_link.STL" />
      </geometry>
      <material
        name="">
        <color
          rgba="0.752941176470588 0.752941176470588 0.752941176470588 1" />
      </material>
    </visual>
    <collision>
      <origin
        xyz="0 0 0"
        rpy="0 0 0" />
      <geometry>
        <mesh
          filename="package://Spot_dog/meshes/rh_lower_link.STL" />
      </geometry>
    </collision>
  </link>
  <joint
    name="rh_lower_joint"
    type="continuous">
    <origin
      xyz="0 -0.00799999999999998 -0.139702359950835"
      rpy="0 0 0" />
    <parent
      link="rh_upper_link" />
    <child
      link="rh_lower_link" />
    <axis
      xyz="0 1 0" />
  </joint>
  <link
    name="rh_foot_link">
    <inertial>
      <origin
        xyz="0.00182657432167069 -1.33204328262027E-08 0.00922281925671403"
        rpy="0 0 0" />
      <mass
        value="0.0268070523816171" />
      <inertia
        ixx="8.14223141565473E-06"
        ixy="3.46629055178195E-12"
        ixz="-8.36660669706648E-07"
        iyy="9.81061759238105E-06"
        iyz="2.96214288334531E-12"
        izz="3.22901712426114E-06" />
    </inertial>
    <visual>
      <origin
        xyz="0 0 0"
        rpy="0 0 0" />
      <geometry>
        <mesh
          filename="package://Spot_dog/meshes/rh_foot_link.STL" />
      </geometry>
      <material
        name="">
        <color
          rgba="0.752941176470588 0.752941176470588 0.752941176470588 1" />
      </material>
    </visual>
    <collision>
      <origin
        xyz="0 0 0"
        rpy="0 0 0" />
      <geometry>
        <mesh
          filename="package://Spot_dog/meshes/rh_foot_link.STL" />
      </geometry>
    </collision>
  </link>
  <joint
    name="rh_foot_joint"
    type="fixed">
    <origin
      xyz="-0.0068961 0.0116 -0.16295"
      rpy="0 0 0" />
    <parent
      link="rh_lower_link" />
    <child
      link="rh_foot_link" />
    <axis
      xyz="0 0 0" />
  </joint>
  <link
    name="lf_hip_link">
    <inertial>
      <origin
        xyz="0.0495269622868717 0.0151217121138406 0.00259304376253863"
        rpy="0 0 0" />
      <mass
        value="0.110796689886985" />
      <inertia
        ixx="4.10359142199375E-05"
        ixy="9.69729499828462E-10"
        ixz="5.2287739474738E-10"
        iyy="0.000105636298090407"
        iyz="-1.805477813767E-06"
        izz="0.00010564295073898" />
    </inertial>
    <visual>
      <origin
        xyz="0 0 0"
        rpy="0 0 0" />
      <geometry>
        <mesh
          filename="package://Spot_dog/meshes/lf_hip_link.STL" />
      </geometry>
      <material
        name="">
        <color
          rgba="0.752941176470588 0.752941176470588 0.752941176470588 1" />
      </material>
    </visual>
    <collision>
      <origin
        xyz="0 0 0"
        rpy="0 0 0" />
      <geometry>
        <mesh
          filename="package://Spot_dog/meshes/lf_hip_link.STL" />
      </geometry>
    </collision>
  </link>
  <joint
    name="lf_hip_axis"
    type="continuous">
    <origin
      xyz="0.1325 0.07989 -0.034298"
      rpy="0 0 0" />
    <parent
      link="base_link" />
    <child
      link="lf_hip_link" />
    <axis
      xyz="1 0 0" />
  </joint>
  <link
    name="lf_upper_link">
    <inertial>
      <origin
        xyz="-0.00214102966052523 -0.00955383710019805 -0.0846823076197817"
        rpy="0 0 0" />
      <mass
        value="0.0381858201318091" />
      <inertia
        ixx="4.56120134594677E-05"
        ixy="-2.39468983332409E-08"
        ixz="-1.71516304037832E-06"
        iyy="4.75905522326161E-05"
        iyz="-6.28798317008029E-07"
        izz="2.56039762142872E-06" />
    </inertial>
    <visual>
      <origin
        xyz="0 0 0"
        rpy="0 0 0" />
      <geometry>
        <mesh
          filename="package://Spot_dog/meshes/lf_upper_link.STL" />
      </geometry>
      <material
        name="">
        <color
          rgba="0.752941176470588 0.752941176470588 0.752941176470588 1" />
      </material>
    </visual>
    <collision>
      <origin
        xyz="0 0 0"
        rpy="0 0 0" />
      <geometry>
        <mesh
          filename="package://Spot_dog/meshes/lf_upper_link.STL" />
      </geometry>
    </collision>
  </link>
  <joint
    name="lf_upper_joint"
    type="continuous">
    <origin
      xyz="0.0270000000000001 0.063175339052324 0.0121192629983798"
      rpy="0 0 0" />
    <parent
      link="lf_hip_link" />
    <child
      link="lf_upper_link" />
    <axis
      xyz="0 0.9999025566156 -0.013959845041636" />
  </joint>
  <link
    name="lf_lower_link">
    <inertial>
      <origin
        xyz="0.000566464370210767 -0.0124219779815389 -0.0659582924607887"
        rpy="0 0 0" />
      <mass
        value="0.0165943030256523" />
      <inertia
        ixx="3.44656313832751E-05"
        ixy="4.04206417528083E-09"
        ixz="2.8952114373848E-07"
        iyy="3.50578354061525E-05"
        iyz="-4.80122859438591E-07"
        izz="6.74753139932655E-07" />
    </inertial>
    <visual>
      <origin
        xyz="0 0 0"
        rpy="0 0 0" />
      <geometry>
        <mesh
          filename="package://Spot_dog/meshes/lf_lower_link.STL" />
      </geometry>
      <material
        name="">
        <color
          rgba="0.752941176470588 0.752941176470588 0.752941176470588 1" />
      </material>
    </visual>
    <collision>
      <origin
        xyz="0 0 0"
        rpy="0 0 0" />
      <geometry>
        <mesh
          filename="package://Spot_dog/meshes/lf_lower_link.STL" />
      </geometry>
    </collision>
  </link>
  <joint
    name="lf_lower_joint"
    type="continuous">
    <origin
      xyz="0 0.00604899715606039 -0.139800425640405"
      rpy="0 0 0" />
    <parent
      link="lf_upper_link" />
    <child
      link="lf_lower_link" />
    <axis
      xyz="0 0.9999025566156 -0.0139598450416295" />
  </joint>
  <link
    name="lf_foot_link">
    <inertial>
      <origin
        xyz="0.00166830267498227 0.00012915397284563 0.00925185669905187"
        rpy="0 0 0" />
      <mass
        value="0.0268070520994839" />
      <inertia
        ixx="8.16945220932775E-06"
        ixy="-1.04945502254447E-08"
        ixz="-7.51936634681799E-07"
        iyy="9.80932980569996E-06"
        iyz="-9.22462199885692E-08"
        izz="3.20308414406131E-06" />
    </inertial>
    <visual>
      <origin
        xyz="0 0 0"
        rpy="0 0 0" />
      <geometry>
        <mesh
          filename="package://Spot_dog/meshes/lf_foot_link.STL" />
      </geometry>
      <material
        name="">
        <color
          rgba="0.752941176470588 0.752941176470588 0.752941176470588 1" />
      </material>
    </visual>
    <collision>
      <origin
        xyz="0 0 0"
        rpy="0 0 0" />
      <geometry>
        <mesh
          filename="package://Spot_dog/meshes/lf_foot_link.STL" />
      </geometry>
    </collision>
  </link>
  <joint
    name="lf_foot_joint"
    type="fixed">
    <origin
      xyz="-0.00410350448816377 -0.0138748986174382 -0.162863312134045"
      rpy="0 0 0" />
    <parent
      link="lf_lower_link" />
    <child
      link="lf_foot_link" />
    <axis
      xyz="0 0 0" />
  </joint>
  <link
    name="lh_hip_link">
    <inertial>
      <origin
        xyz="-0.0494730377009781 0.0150840399972 0.00280388758452487"
        rpy="0 0 0" />
      <mass
        value="0.110796690015489" />
      <inertia
        ixx="4.10359143914821E-05"
        ixy="9.62413318054843E-10"
        ixz="5.35910546574112E-10"
        iyy="0.000105686627480097"
        iyz="-1.80445846591125E-06"
        izz="0.000105592621445254" />
    </inertial>
    <visual>
      <origin
        xyz="0 0 0"
        rpy="0 0 0" />
      <geometry>
        <mesh
          filename="package://Spot_dog/meshes/lh_hip_link.STL" />
      </geometry>
      <material
        name="">
        <color
          rgba="0.752941176470588 0.752941176470588 0.752941176470588 1" />
      </material>
    </visual>
    <collision>
      <origin
        xyz="0 0 0"
        rpy="0 0 0" />
      <geometry>
        <mesh
          filename="package://Spot_dog/meshes/lh_hip_link.STL" />
      </geometry>
    </collision>
  </link>
  <joint
    name="lh_hip_joint"
    type="continuous">
    <origin
      xyz="-0.1325 0.0798899999999998 -0.0342976400491648"
      rpy="0 0 0" />
    <parent
      link="base_link" />
    <child
      link="lh_hip_link" />
    <axis
      xyz="1 0 0" />
  </joint>
  <link
    name="lh_upper_link">
    <inertial>
      <origin
        xyz="-0.00214102966159083 -0.00837075417213326 -0.084807426154219"
        rpy="0 0 0" />
      <mass
        value="0.0381858200550616" />
      <inertia
        ixx="4.5612013465939E-05"
        ixy="-1.15444746288946E-12"
        ixz="-1.7153302049211E-06"
        iyy="4.75993310281756E-05"
        iyz="-5.14326205635436E-13"
        izz="2.55161882950459E-06" />
    </inertial>
    <visual>
      <origin
        xyz="0 0 0"
        rpy="0 0 0" />
      <geometry>
        <mesh
          filename="package://Spot_dog/meshes/lh_upper_link.STL" />
      </geometry>
      <material
        name="">
        <color
          rgba="0.752941176470588 0.752941176470588 0.752941176470588 1" />
      </material>
    </visual>
    <collision>
      <origin
        xyz="0 0 0"
        rpy="0 0 0" />
      <geometry>
        <mesh
          filename="package://Spot_dog/meshes/lh_upper_link.STL" />
      </geometry>
    </collision>
  </link>
  <joint
    name="lh_upper_joint"
    type="continuous">
    <origin
      xyz="-0.072 0.0630000000000001 0.0130000000000001"
      rpy="0 0 0" />
    <parent
      link="lh_hip_link" />
    <child
      link="lh_upper_link" />
    <axis
      xyz="0 1 0" />
  </joint>
  <link
    name="lh_lower_link">
    <inertial>
      <origin
        xyz="0.000566464370210823 -0.0115 -0.0661252741492749"
        rpy="0 0 0" />
      <mass
        value="0.0165943030256523" />
      <inertia
        ixx="3.44656313832752E-05"
        ixy="8.98930417878199E-23"
        ixz="2.89549358407913E-07"
        iyy="3.50645385000434E-05"
        iyz="-6.05251913313224E-21"
        izz="6.68050046041791E-07" />
    </inertial>
    <visual>
      <origin
        xyz="0 0 0"
        rpy="0 0 0" />
      <geometry>
        <mesh
          filename="package://Spot_dog/meshes/lh_lower_link.STL" />
      </geometry>
      <material
        name="">
        <color
          rgba="0.752941176470588 0.752941176470588 0.752941176470588 1" />
      </material>
    </visual>
    <collision>
      <origin
        xyz="0 0 0"
        rpy="0 0 0" />
      <geometry>
        <mesh
          filename="package://Spot_dog/meshes/lh_lower_link.STL" />
      </geometry>
    </collision>
  </link>
  <joint
    name="lh_lower_joint"
    type="continuous">
    <origin
      xyz="0 0.00799999999999995 -0.139702359950834"
      rpy="0 0 0" />
    <parent
      link="lh_upper_link" />
    <child
      link="lh_lower_link" />
    <axis
      xyz="0 1 0" />
  </joint>
  <link
    name="lh_foot_link">
    <inertial>
      <origin
        xyz="0.00166830267317924 -1.30935577657976E-08 0.00925275812454851"
        rpy="0 0 0" />
      <mass
        value="0.0268070520797913" />
      <inertia
        ixx="8.1694522156077E-06"
        ixy="3.39146873062132E-12"
        ixz="-7.52009876424456E-07"
        iyy="9.8106176449227E-06"
        iyz="2.92422848968183E-12"
        izz="3.20179631466342E-06" />
    </inertial>
    <visual>
      <origin
        xyz="0 0 0"
        rpy="0 0 0" />
      <geometry>
        <mesh
          filename="package://Spot_dog/meshes/lh_foot_link.STL" />
      </geometry>
      <material
        name="">
        <color
          rgba="0.752941176470588 0.752941176470588 0.752941176470588 1" />
      </material>
    </visual>
    <collision>
      <origin
        xyz="0 0 0"
        rpy="0 0 0" />
      <geometry>
        <mesh
          filename="package://Spot_dog/meshes/lh_foot_link.STL" />
      </geometry>
    </collision>
  </link>
  <joint
    name="lh_foot_joint"
    type="fixed">
    <origin
      xyz="-0.0041035 -0.0116 -0.16304"
      rpy="0 0 0" />
    <parent
      link="lh_lower_link" />
    <child
      link="lh_foot_link" />
    <axis
      xyz="0 0 0" />
  </joint>
</robot>